{
 "cells": [
  {
   "cell_type": "markdown",
   "metadata": {
    "slideshow": {
     "slide_type": "slide"
    }
   },
   "source": [
    "## Errors and Exceptions\n",
    "Until now error messages haven’t been more than mentioned, but if you have tried out the examples you have probably seen some. There are (at least) two distinguishable kinds of errors: **syntax errors** and **exceptions**"
   ]
  },
  {
   "cell_type": "markdown",
   "metadata": {
    "slideshow": {
     "slide_type": "subslide"
    }
   },
   "source": [
    "## Syntax Errors\n",
    "\n",
    "Syntax errors, also known as parsing errors, are perhaps the most common kind of complaint you get while you are still learning Python\n",
    "```python\n",
    ">>> while True print('Hello world')\n",
    "  File \"<stdin>\", line 1\n",
    "    while True print('Hello world')\n",
    "                   ^\n",
    "SyntaxError: invalid syntax\n",
    "```"
   ]
  },
  {
   "cell_type": "markdown",
   "metadata": {
    "slideshow": {
     "slide_type": "subslide"
    }
   },
   "source": [
    "The parser repeats the offending line and displays a little ‘arrow’ pointing at the earliest point in the line where the error was detected. The error is caused by (or at least detected at) the token preceding the arrow\n",
    "\n"
   ]
  },
  {
   "cell_type": "markdown",
   "metadata": {
    "slideshow": {
     "slide_type": "slide"
    }
   },
   "source": [
    "## Exceptions\n",
    "\n",
    "* Even if a statement or expression is syntactically correct, it may cause an error when an attempt is made to execute it. \n",
    "\n",
    "* Errors detected during execution are called `exceptions` and are not unconditionally fatal: \n",
    "\n",
    "* Most exceptions are not handled by programs, however, and result in error messages"
   ]
  },
  {
   "cell_type": "markdown",
   "metadata": {
    "slideshow": {
     "slide_type": "subslide"
    }
   },
   "source": [
    "```python\n",
    ">>> 10 * (1/0)\n",
    "Traceback (most recent call last):\n",
    "  File \"<stdin>\", line 1, in <module>\n",
    "ZeroDivisionError: division by zero\n",
    ">>> 4 + spam*3\n",
    "Traceback (most recent call last):\n",
    "  File \"<stdin>\", line 1, in <module>\n",
    "NameError: name 'spam' is not defined\n",
    ">>> '2' + 2\n",
    "Traceback (most recent call last):\n",
    "  File \"<stdin>\", line 1, in <module>\n",
    "TypeError: Can't convert 'int' object to str implicitly\n",
    "```"
   ]
  },
  {
   "cell_type": "markdown",
   "metadata": {
    "slideshow": {
     "slide_type": "subslide"
    }
   },
   "source": [
    "The last line of the error message indicates what happened. Exceptions come in different types, and the type is printed as part of the message\n",
    "\n",
    "The rest of the line provides detail based on the type of exception and what caused it.\n",
    "\n",
    "The preceding part of the error message shows the context where the exception happened, in the form of a stack traceback. In general it contains a stack traceback listing source lines"
   ]
  },
  {
   "cell_type": "markdown",
   "metadata": {
    "slideshow": {
     "slide_type": "slide"
    }
   },
   "source": [
    "## Handling Exceptions\n",
    "\n",
    "It is possible to write programs that handle selected exceptions."
   ]
  },
  {
   "cell_type": "markdown",
   "metadata": {
    "slideshow": {
     "slide_type": "fragment"
    }
   },
   "source": [
    "```python\n",
    ">>> while True:\n",
    "...     try:\n",
    "...         x = int(input(\"Please enter a number: \"))\n",
    "...         break\n",
    "...     except ValueError:\n",
    "...         print(\"Oops!  That was no valid number.  Try again...\")\n",
    "...\n",
    "```"
   ]
  },
  {
   "cell_type": "markdown",
   "metadata": {
    "slideshow": {
     "slide_type": "subslide"
    }
   },
   "source": [
    "#### The `try` statement\n",
    "First, the try clause (the statement(s) between the try and except keywords) is executed.\n",
    "\n",
    "*   If no exception occurs, the except clause is skipped and execution of the try statement is finished.\n",
    "\n",
    "*   If an exception occurs during execution of the try clause, the rest of the clause is skipped. Then if its type matches the exception named after the except keyword, the except clause is executed, and then execution continues after the try statement.\n",
    "\n",
    "*   If an exception occurs which does not match the exception named in the except clause, it is passed on to outer try statements; if no handler is found, it is an unhandled exception and execution stops with a message as shown above.\n",
    "\n",
    "* A try statement may have more than one except clause, to specify handlers for different exceptions"
   ]
  },
  {
   "cell_type": "markdown",
   "metadata": {
    "slideshow": {
     "slide_type": "slide"
    }
   },
   "source": [
    "## Raising Exceptions\n",
    "\n",
    "The raise statement allows the programmer to force a specified exception to occur. For example:\n",
    "```python\n",
    ">>> raise NameError('HiThere')\n",
    "Traceback (most recent call last):\n",
    "  File \"<stdin>\", line 1, in <module>\n",
    "NameError: HiThere\n",
    "```\n",
    "The sole argument to raise indicates the exception to be raised. This must be either an exception instance or an exception class"
   ]
  },
  {
   "cell_type": "markdown",
   "metadata": {
    "slideshow": {
     "slide_type": "slide"
    }
   },
   "source": [
    "## User-defined Exceptions\n",
    "\n",
    "* Programs may name their own exceptions by creating a new exception class \n",
    "\n",
    "* Exceptions should typically be derived from the `Exception` class, either directly or indirectly."
   ]
  },
  {
   "cell_type": "markdown",
   "metadata": {
    "slideshow": {
     "slide_type": "fragment"
    }
   },
   "source": [
    "\n",
    "* Exception classes can be defined which do anything any other class can do\n",
    "    * Usually kept simple, often only a number of attributes that allow information about the error to be extracted by handlers for the exception. \n",
    "\n",
    "* When creating a module that can raise several distinct errors, a common practice is to create a base class for exceptions defined by that module, and subclass that create specific exception classes for different error conditions:\n"
   ]
  },
  {
   "cell_type": "code",
   "execution_count": 1,
   "metadata": {
    "slideshow": {
     "slide_type": "subslide"
    }
   },
   "outputs": [],
   "source": [
    "class Error(Exception):\n",
    "    \"\"\"Base class for exceptions in this module.\"\"\"\n",
    "    pass\n",
    "\n",
    "class InputError(Error):\n",
    "    \"\"\"Exception raised for errors in the input.\n",
    "\n",
    "    Attributes:\n",
    "        expression -- input expression in which the error occurred\n",
    "        message -- explanation of the error\n",
    "    \"\"\"\n",
    "\n",
    "    def __init__(self, expression, message):\n",
    "        self.expression = expression\n",
    "        self.message = message"
   ]
  },
  {
   "cell_type": "code",
   "execution_count": 2,
   "metadata": {
    "slideshow": {
     "slide_type": "subslide"
    }
   },
   "outputs": [],
   "source": [
    "\n",
    "class TransitionError(Error):\n",
    "    \"\"\"Raised when an operation attempts a state transition that's not\n",
    "    allowed.\n",
    "\n",
    "    Attributes:\n",
    "        previous -- state at beginning of transition\n",
    "        next -- attempted new state\n",
    "        message -- explanation of why the specific transition is not allowed\n",
    "    \"\"\"\n",
    "\n",
    "    def __init__(self, previous, next, message):\n",
    "        self.previous = previous\n",
    "        self.next = next\n",
    "        self.message = message\n"
   ]
  },
  {
   "cell_type": "markdown",
   "metadata": {
    "slideshow": {
     "slide_type": "subslide"
    }
   },
   "source": [
    "* Most exceptions are defined with names that end in “Error”, similar to the naming of the standard exceptions\n",
    "\n",
    "* Many standard modules define their own exceptions to report errors that may occur in functions they define"
   ]
  },
  {
   "cell_type": "markdown",
   "metadata": {
    "slideshow": {
     "slide_type": "slide"
    }
   },
   "source": [
    "## Defining Clean-up Actions\n",
    "\n",
    "The try statement has another optional clause which is intended to define clean-up actions\n",
    "```python\n",
    "try:\n",
    "    raise KeyboardInterrupt\n",
    "finally:\n",
    "    print('Goodbye, world!')\n",
    "\n",
    "Goodbye, world!\n",
    "KeyboardInterrupt\n",
    "Traceback (most recent call last):\n",
    "  File \"<stdin>\", line 2, in <module>\n",
    "```"
   ]
  },
  {
   "cell_type": "markdown",
   "metadata": {
    "slideshow": {
     "slide_type": "subslide"
    }
   },
   "source": [
    "* A `finally` clause is always executed before leaving the try statement, whether an exception has occurred or not.\n",
    "\n",
    "* When an exception has occurred in the `try` clause and has not been handled by an `except` clause (or it has occurred in an `except` or `else` clause), it is re-raised after the `finally` clause has been executed.\n",
    "\n",
    "* The `finally` clause is also executed “on the way out” when any other clause of the `try` statement is left via a `break`, `continue` or `return` statement"
   ]
  },
  {
   "cell_type": "markdown",
   "metadata": {
    "slideshow": {
     "slide_type": "subslide"
    }
   },
   "source": [
    "```python\n",
    ">>> def divide(x, y):\n",
    "...     try:\n",
    "...         result = x / y\n",
    "...     except ZeroDivisionError:\n",
    "...         print(\"division by zero!\")\n",
    "...     else:\n",
    "...         print(\"result is\", result)\n",
    "...     finally:\n",
    "...         print(\"executing finally clause\")\n",
    "...\n",
    ">>> divide(2, 1)\n",
    "result is 2.0\n",
    "executing finally clause\n",
    ">>> divide(2, 0)\n",
    "division by zero!\n",
    "executing finally clause\n",
    ">>> divide(\"2\", \"1\")\n",
    "executing finally clause\n",
    "# As you can see, the finally clause is executed in any event\n",
    "Traceback (most recent call last):\n",
    "  File \"<stdin>\", line 1, in <module>\n",
    "  File \"<stdin>\", line 3, in divide\n",
    "TypeError: unsupported operand type(s) for /: 'str' and 'str'\n",
    "# The TypeError raised by dividing two strings is not handled by the except clause and therefore re-raised after finally runs\n",
    "```"
   ]
  },
  {
   "cell_type": "markdown",
   "metadata": {
    "slideshow": {
     "slide_type": "subslide"
    }
   },
   "source": [
    "\n",
    "In real world applications, the finally clause is useful for releasing external resources (such as files or network connections), regardless of whether the use of the resource was successful."
   ]
  },
  {
   "cell_type": "markdown",
   "metadata": {
    "slideshow": {
     "slide_type": "slide"
    }
   },
   "source": [
    "\n",
    "## Predefined Clean-up Actions\n",
    "\n",
    "Some objects define standard clean-up actions to be undertaken when the object is no longer needed, regardless of whether or not the operation using the object succeeded or failed. \n",
    "\n",
    "```python\n",
    "for line in open(\"myfile.txt\"):\n",
    "    print(line, end=\"\")\n",
    "```\n"
   ]
  },
  {
   "cell_type": "markdown",
   "metadata": {
    "slideshow": {
     "slide_type": "fragment"
    }
   },
   "source": [
    "\n",
    "* The problem with this code is that it leaves the file open for an indeterminate amount of time after this part of the code has finished executing. \n",
    "\n",
    "* This is not an issue in simple scripts, but can be a problem for larger applications. \n"
   ]
  },
  {
   "cell_type": "markdown",
   "metadata": {
    "slideshow": {
     "slide_type": "subslide"
    }
   },
   "source": [
    "\n",
    "```python\n",
    "with open(\"myfile.txt\") as f:\n",
    "    for line in f:\n",
    "        print(line, end=\"\")\n",
    "```\n",
    "\n",
    "* After the statement is executed, the file `f` is always closed, even if a problem was encountered while processing the lines. \n",
    "\n",
    "* Objects which, like files, provide predefined clean-up actions will indicate this in their documentation.\n"
   ]
  }
 ],
 "metadata": {
  "celltoolbar": "Slideshow",
  "kernelspec": {
   "display_name": "Python 3",
   "language": "python",
   "name": "python3"
  },
  "language_info": {
   "codemirror_mode": {
    "name": "ipython",
    "version": 3
   },
   "file_extension": ".py",
   "mimetype": "text/x-python",
   "name": "python",
   "nbconvert_exporter": "python",
   "pygments_lexer": "ipython3",
   "version": "3.7.4"
  }
 },
 "nbformat": 4,
 "nbformat_minor": 2
}
